Traceback (most recent call last):
  File "/opt/hostedtoolcache/Python/3.9.17/x64/lib/python3.9/site-packages/jupyter_cache/executors/utils.py", line 58, in single_nb_execution
    executenb(
  File "/opt/hostedtoolcache/Python/3.9.17/x64/lib/python3.9/site-packages/nbclient/client.py", line 1305, in execute
    return NotebookClient(nb=nb, resources=resources, km=km, **kwargs).execute()
  File "/opt/hostedtoolcache/Python/3.9.17/x64/lib/python3.9/site-packages/jupyter_core/utils/__init__.py", line 166, in wrapped
    return loop.run_until_complete(inner)
  File "/opt/hostedtoolcache/Python/3.9.17/x64/lib/python3.9/asyncio/base_events.py", line 647, in run_until_complete
    return future.result()
  File "/opt/hostedtoolcache/Python/3.9.17/x64/lib/python3.9/site-packages/nbclient/client.py", line 705, in async_execute
    await self.async_execute_cell(
  File "/opt/hostedtoolcache/Python/3.9.17/x64/lib/python3.9/site-packages/nbclient/client.py", line 1058, in async_execute_cell
    await self._check_raise_for_error(cell, cell_index, exec_reply)
  File "/opt/hostedtoolcache/Python/3.9.17/x64/lib/python3.9/site-packages/nbclient/client.py", line 914, in _check_raise_for_error
    raise CellExecutionError.from_cell_and_msg(cell, exec_reply_content)
nbclient.exceptions.CellExecutionError: An error occurred while executing the following cell:
------------------
from pathlib import Path
import yaml
import networkx as nx

models = [
    "floris",
    "openfast",
    "rosco",
    "weis",
    "wisdem",
    "windse",
]
model_connectivity = {}
for model in models:
    attributes = yaml.safe_load( open(Path("..", "..", "software_attributes", "database", f"{model}.yaml"), "r") )
    model_connectivity[model] = attributes["dependencies"]

network_graph = nx.DiGraph()
for model, connections in model_connectivity.items():
    for c in connections:
        weight = 1 if c[1] == "direct" else 2
        network_graph.add_edge(model, c[0], weight=weight)
------------------


[0;31m---------------------------------------------------------------------------[0m
[0;31mModuleNotFoundError[0m                       Traceback (most recent call last)
Cell [0;32mIn[1], line 3[0m
[1;32m      1[0m [38;5;28;01mfrom[39;00m [38;5;21;01mpathlib[39;00m [38;5;28;01mimport[39;00m Path
[1;32m      2[0m [38;5;28;01mimport[39;00m [38;5;21;01myaml[39;00m
[0;32m----> 3[0m [38;5;28;01mimport[39;00m [38;5;21;01mnetworkx[39;00m [38;5;28;01mas[39;00m [38;5;21;01mnx[39;00m
[1;32m      5[0m models [38;5;241m=[39m [
[1;32m      6[0m     [38;5;124m"[39m[38;5;124mfloris[39m[38;5;124m"[39m,
[1;32m      7[0m     [38;5;124m"[39m[38;5;124mopenfast[39m[38;5;124m"[39m,
[0;32m   (...)[0m
[1;32m     11[0m     [38;5;124m"[39m[38;5;124mwindse[39m[38;5;124m"[39m,
[1;32m     12[0m ]
[1;32m     13[0m model_connectivity [38;5;241m=[39m {}

[0;31mModuleNotFoundError[0m: No module named 'networkx'

